テスト > アサート
# 例外
指定した例外が起こればOK  
```python
with self.assertRaises(例外, msg='めっせーじ'):
	例外が起こる処理
```
